<?xml version="1.0" encoding="UTF-8"?>
<!-- Generated by org.testng.reporters.JUnitReportReporter -->
<testsuite skipped="3" hostname="ISHU-PC" name="testcases.TC002_LoginForFailure" tests="9" failures="0" timestamp="25 Jun 2018 11:18:27 GMT" time="68.831" errors="2">
  <testcase name="loginAndLogout" time="9.667" classname="testcases.TC002_LoginForFailure">
    <skipped/>
  </testcase> <!-- loginAndLogout -->
  <testcase name="loginAndLogout" time="13.299" classname="testcases.TC002_LoginForFailure"/>
  <testcase name="loginAndLogout" time="0.000" classname="testcases.TC002_LoginForFailure">
    <skipped/>
  </testcase> <!-- loginAndLogout -->
  <testcase name="afterMethod" time="0.575" classname="testcases.TC002_LoginForFailure">
    <error type="java.lang.RuntimeException">
      <![CDATA[java.lang.RuntimeException
at utils.Reporter.reportStep(Reporter.java:60)
at wdMethods.SeMethods.closeAllBrowsers(SeMethods.java:385)
at wdMethods.ProjectMethods.afterMethod(ProjectMethods.java:47)
at sun.reflect.NativeMethodAccessorImpl.invoke0(Native Method)
at sun.reflect.NativeMethodAccessorImpl.invoke(Unknown Source)
at sun.reflect.DelegatingMethodAccessorImpl.invoke(Unknown Source)
at java.lang.reflect.Method.invoke(Unknown Source)
at org.testng.internal.MethodInvocationHelper.invokeMethod(MethodInvocationHelper.java:124)
at org.testng.internal.MethodInvocationHelper.invokeMethodConsideringTimeout(MethodInvocationHelper.java:59)
at org.testng.internal.Invoker.invokeConfigurationMethod(Invoker.java:458)
at org.testng.internal.Invoker.invokeConfigurations(Invoker.java:222)
at org.testng.internal.Invoker.invokeMethod(Invoker.java:646)
at org.testng.internal.Invoker.invokeTestMethod(Invoker.java:719)
at org.testng.internal.Invoker.invokeTestMethods(Invoker.java:989)
at org.testng.internal.TestMethodWorker.invokeTestMethods(TestMethodWorker.java:125)
at org.testng.internal.TestMethodWorker.run(TestMethodWorker.java:109)
at org.testng.TestRunner.privateRun(TestRunner.java:648)
at org.testng.TestRunner.run(TestRunner.java:505)
at org.testng.SuiteRunner.runTest(SuiteRunner.java:455)
at org.testng.SuiteRunner.access$000(SuiteRunner.java:40)
at org.testng.SuiteRunner$SuiteWorker.run(SuiteRunner.java:489)
at org.testng.internal.thread.ThreadUtil$1.call(ThreadUtil.java:52)
at java.util.concurrent.FutureTask.run(Unknown Source)
at java.util.concurrent.ThreadPoolExecutor.runWorker(Unknown Source)
at java.util.concurrent.ThreadPoolExecutor$Worker.run(Unknown Source)
at java.lang.Thread.run(Unknown Source)
]]>
    </error>
  </testcase> <!-- afterMethod -->
  <testcase name="loginAndLogout" time="9.546" classname="testcases.TC002_LoginForFailure"/>
  <testcase name="loginAndLogout" time="17.055" classname="testcases.TC002_LoginForFailure">
    <error type="java.lang.RuntimeException">
      <![CDATA[java.lang.RuntimeException
at utils.Reporter.reportStep(Reporter.java:60)
at utils.Reporter.reportStep(Reporter.java:70)
at wdMethods.SeMethods.click(SeMethods.java:135)
at pages.LoginPage.clickLogInForFailer(LoginPage.java:47)
at testcases.TC002_LoginForFailure.loginAndLogout(TC002_LoginForFailure.java:28)
at sun.reflect.NativeMethodAccessorImpl.invoke0(Native Method)
at sun.reflect.NativeMethodAccessorImpl.invoke(Unknown Source)
at sun.reflect.DelegatingMethodAccessorImpl.invoke(Unknown Source)
at java.lang.reflect.Method.invoke(Unknown Source)
at org.testng.internal.MethodInvocationHelper.invokeMethod(MethodInvocationHelper.java:124)
at org.testng.internal.Invoker.invokeMethod(Invoker.java:583)
at org.testng.internal.Invoker.invokeTestMethod(Invoker.java:719)
at org.testng.internal.Invoker.invokeTestMethods(Invoker.java:989)
at org.testng.internal.TestMethodWorker.invokeTestMethods(TestMethodWorker.java:125)
at org.testng.internal.TestMethodWorker.run(TestMethodWorker.java:109)
at org.testng.TestRunner.privateRun(TestRunner.java:648)
at org.testng.TestRunner.run(TestRunner.java:505)
at org.testng.SuiteRunner.runTest(SuiteRunner.java:455)
at org.testng.SuiteRunner.access$000(SuiteRunner.java:40)
at org.testng.SuiteRunner$SuiteWorker.run(SuiteRunner.java:489)
at org.testng.internal.thread.ThreadUtil$1.call(ThreadUtil.java:52)
at java.util.concurrent.FutureTask.run(Unknown Source)
at java.util.concurrent.ThreadPoolExecutor.runWorker(Unknown Source)
at java.util.concurrent.ThreadPoolExecutor$Worker.run(Unknown Source)
at java.lang.Thread.run(Unknown Source)
]]>
    </error>
  </testcase> <!-- loginAndLogout -->
  <testcase name="loginAndLogout" time="11.750" classname="testcases.TC002_LoginForFailure"/>
  <testcase name="loginAndLogout" time="0.000" classname="testcases.TC002_LoginForFailure">
    <skipped/>
  </testcase> <!-- loginAndLogout -->
  <testcase name="loginAndLogout" time="6.939" classname="testcases.TC002_LoginForFailure"/>
</testsuite> <!-- testcases.TC002_LoginForFailure -->
